package calculadora;

import static org.junit.Assert.fail;

import java.util.ArrayList;
import java.util.List;

import org.junit.Test;

public class ExceptionTest {

	//Erro esperado
	@Test
	public void testExeptionMessage() {
		try {
			//pegamos primeiro objeto que não existe retornando exceção
			new ArrayList<Object>().get(0);
			fail("Esperado que IndexOutOfBoundsException seja lançada");
		} catch (IndexOutOfBoundsException ex) {
			//System.out.println("Exception foi gerada.");
		}
	}
	
}
